Workbook

Sheet Болгов
A1: Эксперт: Болгов
A3: Таблица 1. Важность критериев
A4: Критерий | B4: Пессимистичная | C4: Ожидаемая | D4: Оптимистичная
A5: Востребованность | B5: 6 | C5: 7 | D5: 8
A6: Простота реализации | B6: 7 | C6: 8 | D6: 9
A7: Интерес команды | B7: 5 | C7: 6 | D7: 7
A8: Масштабируемость | B8: 3 | C8: 4 | D8: 5
A10: Таблица 2. Оценка концепций по критериям
A11: Концепция | B11: Критерий | C11: Пессимистичная | D11: Ожидаемая | E11: Оптимистичная
A12: Таск-менеджер | B12: Востребованность | C12: 7 | D12: 8 | E12: 9
A13: Таск-менеджер | B13: Простота реализации | C13: 4 | D13: 5 | E13: 6
A14: Таск-менеджер | B14: Интерес команды | C14: 4 | D14: 5 | E14: 6
A15: Таск-менеджер | B15: Масштабируемость | C15: 7 | D15: 8 | E15: 9
A16: Органайзер изображений | B16: Востребованность | C16: 4 | D16: 5 | E16: 6
A17: Органайзер изображений | B17: Простота реализации | C17: 3 | D17: 4 | E17: 5
A18: Органайзер изображений | B18: Интерес команды | C18: 5 | D18: 6 | E18: 7
A19: Органайзер изображений | B19: Масштабируемость | C19: 4 | D19: 5 | E19: 6
A20: Менеджер паролей | B20: Востребованность | C20: 6 | D20: 7 | E20: 8
A21: Менеджер паролей | B21: Простота реализации | C21: 3 | D21: 4 | E21: 5
A22: Менеджер паролей | B22: Интерес команды | C22: 4 | D22: 5 | E22: 6
A23: Менеджер паролей | B23: Масштабируемость | C23: 3 | D23: 4 | E23: 5
... A27: Markdown-редактор | B27: Масштабируемость | C27: 5 | D27: 6 | E27: 7

Sheet Спицин
A1: Эксперт: Спицин
A3: Таблица 1. Важность критериев
A4: Критерий | B4: Пессимистичная | C4: Ожидаемая | D4: Оптимистичная
A5: Востребованность | B5: 5 | C5: 6 | D5: 7
A6: Простота реализации | B6: 6 | C6: 7 | D6: 8
A7: Интерес команды | B7: 6 | C7: 7 | D7: 8
A8: Масштабируемость | B8: 3 | C8: 4 | D8: 6
A10: Таблица 2. Оценка концепций по критериям
A11: Концепция | B11: Критерий | C11: Пессимистичная | D11: Ожидаемая | E11: Оптимистичная
A12: Таск-менеджер | B12: Востребованность | C12: 7 | D12: 8 | E12: 9
A13: Таск-менеджер | B13: Простота реализации | C13: 4 | D13: 5 | E13: 7
A14: Таск-менеджер | B14: Интерес команды | C14: 3 | D14: 5 | E14: 6
A15: Таск-менеджер | B15: Масштабируемость | C15: 7 | D15: 8 | E15: 9
A16: Органайзер изображений | B16: Востребованность | C16: 4 | D16: 5 | E16: 6
A17: Органайзер изображений | B17: Простота реализации | C17: 3 | D17: 4 | E17: 5
A18: Органайзер изображений | B18: Интерес команды | C18: 5 | D18: 6 | E18: 8
A19: Органайзер изображений | B19: Масштабируемость | C19: 4 | D19: 5 | E19: 6
A20: Менеджер паролей | B20: Востребованность | C20: 6 | D20: 7 | E20: 8
A21: Менеджер паролей | B21: Простота реализации | C21: 3 | D21: 4 | E21: 6
A22: Менеджер паролей | B22: Интерес команды | C22: 4 | D22: 5 | E22: 6
A23: Менеджер паролей | B23: Масштабируемость | C23: 3 | D23: 4 | E23: 5
... A27: Markdown-редактор | B27: Масштабируемость | C27: 4 | D27: 6 | E27: 7

Sheet Гуров
A1: Эксперт: Гуров
A3: Таблица 1. Важность критериев
A4: Критерий | B4: Пессимистичная | C4: Ожидаемая | D4: Оптимистичная
A5: Востребованность | B5: 6 | C5: 7 | D5: 8
A6: Простота реализации | B6: 7 | C6: 8 | D6: 9
A7: Интерес команды | B7: 4 | C7: 5 | D7: 7
A8: Масштабируемость | B8: 2 | C8: 4 | D8: 5
A10: Таблица 2. Оценка концепций по критериям
A11: Концепция | B11: Критерий | C11: Пессимистичная | D11: Ожидаемая | E11: Оптимистичная
A12: Таск-менеджер | B12: Востребованность | C12: 7 | D12: 8 | E12: 9
A13: Таск-менеджер | B13: Простота реализации | C13: 5 | D13: 6 | E13: 7
A14: Таск-менеджер | B14: Интерес команды | C14: 3 | D14: 4 | E14: 5
A15: Таск-менеджер | B15: Масштабируемость | C15: 6 | D15: 8 | E15: 9
A16: Органайзер изображений | B16: Востребованность | C16: 3 | D16: 5 | E16: 6
A17: Органайзер изображений | B17: Простота реализации | C17: 3 | D17: 4 | E17: 5
A18: Органайзер изображений | B18: Интерес команды | C18: 5 | D18: 6 | E18: 7
A19: Органайзер изображений | B19: Масштабируемость | C19: 4 | D19: 5 | E19: 6
A20: Менеджер паролей | B20: Востребованность | C20: 6 | D20: 7 | E20: 9
A21: Менеджер паролей | B21: Простота реализации | C21: 2 | D21: 3 | E21: 5
A22: Менеджер паролей | B22: Интерес команды | C22: 4 | D22: 5 | E22: 6
A23: Менеджер паролей | B23: Масштабируемость | C23: 3 | D23: 4 | E23: 5
... A27: Markdown-редактор | B27: Масштабируемость | C27: 5 | D27: 6 | E27: 7

Sheet Сводка
A1: Сводка: среднее по трём экспертам
A3: Таблица 1. Важность критериев
A4: Критерий | B4: Пессимистичная | C4: Ожидаемая | D4: Оптимистичная
A5: Востребованность | B5: =AVERAGE(Болгов!B5,Спицин!B5,Гуров!B5) -> 5.6666667 | C5: =AVERAGE(Болгов!C5,Спицин!C5,Гуров!C5) -> 6.6666667 | D5: =AVERAGE(Болгов!D5,Спицин!D5,Гуров!D5) -> 7.6666667
A6: Простота реализации | B6: =AVERAGE(Болгов!B6,Спицин!B6,Гуров!B6) -> 6.6666667 | C6: =AVERAGE(Болгов!C6,Спицин!C6,Гуров!C6) -> 7.6666667 | D6: =AVERAGE(Болгов!D6,Спицин!D6,Гуров!D6) -> 8.6666667
A7: Интерес команды | B7: =AVERAGE(Болгов!B7,Спицин!B7,Гуров!B7) -> 5 | C7: =AVERAGE(Болгов!C7,Спицин!C7,Гуров!C7) -> 6 | D7: =AVERAGE(Болгов!D7,Спицин!D7,Гуров!D7) -> 7.3333333
A8: Масштабируемость | B8: =AVERAGE(Болгов!B8,Спицин!B8,Гуров!B8) -> 2.6666667 | C8: =AVERAGE(Болгов!C8,Спицин!C8,Гуров!C8) -> 4 | D8: =AVERAGE(Болгов!D8,Спицин!D8,Гуров!D8) -> 5.3333333
A10: Таблица 2. Оценка концепций по критериям
A11: Концепция | B11: Критерий | C11: Пессимистичная | D11: Ожидаемая | E11: Оптимистичная
A12: Таск-менеджер | B12: Востребованность | C12: =AVERAGE(Болгов!C12,Спицин!C12,Гуров!C12) -> 7 | D12: =AVERAGE(Болгов!D12,Спицин!D12,Гуров!D12) -> 8 | E12: =AVERAGE(Болгов!E12,Спицин!E12,Гуров!E12) -> 9
A13: Таск-менеджер | B13: Простота реализации | C13: =AVERAGE(Болгов!C13,Спицин!C13,Гуров!C13) -> 4.3333333 | D13: =AVERAGE(Болгов!D13,Спицин!D13,Гуров!D13) -> 5.3333333 | E13: =AVERAGE(Болгов!E13,Спицин!E13,Гуров!E13) -> 6.6666667
A14: Таск-менеджер | B14: Интерес команды | C14: =AVERAGE(Болгов!C14,Спицин!C14,Гуров!C14) -> 3.3333333 | D14: =AVERAGE(Болгов!D14,Спицин!D14,Гуров!D14) -> 4.6666667 | E14: =AVERAGE(Болгов!E14,Спицин!E14,Гуров!E14) -> 5.6666667
A15: Таск-менеджер | B15: Масштабируемость | C15: =AVERAGE(Болгов!C15,Спицин!C15,Гуров!C15) -> 6.6666667 | D15: =AVERAGE(Болгов!D15,Спицин!D15,Гуров!D15) -> 8 | E15: =AVERAGE(Болгов!E15,Спицин!E15,Гуров!E15) -> 9
A16: Органайзер изображений | B16: Востребованность | C16: =AVERAGE(Болгов!C16,Спицин!C16,Гуров!C16) -> 3.6666667 | D16: =AVERAGE(Болгов!D16,Спицин!D16,Гуров!D16) -> 5 | E16: =AVERAGE(Болгов!E16,Спицин!E16,Гуров!E16) -> 6
A17: Органайзер изображений | B17: Простота реализации | C17: =AVERAGE(Болгов!C17,Спицин!C17,Гуров!C17) -> 3 | D17: =AVERAGE(Болгов!D17,Спицин!D17,Гуров!D17) -> 4 | E17: =AVERAGE(Болгов!E17,Спицин!E17,Гуров!E17) -> 5
A18: Органайзер изображений | B18: Интерес команды | C18: =AVERAGE(Болгов!C18,Спицин!C18,Гуров!C18) -> 5 | D18: =AVERAGE(Болгов!D18,Спицин!D18,Гуров!D18) -> 6 | E18: =AVERAGE(Болгов!E18,Спицин!E18,Гуров!E18) -> 7.3333333
A19: Органайзер изображений | B19: Масштабируемость | C19: =AVERAGE(Болгов!C19,Спицин!C19,Гуров!C19) -> 4 | D19: =AVERAGE(Болгов!D19,Спицин!D19,Гуров!D19) -> 5 | E19: =AVERAGE(Болгов!E19,Спицин!E19,Гуров!E19) -> 6
A20: Менеджер паролей | B20: Востребованность | C20: =AVERAGE(Болгов!C20,Спицин!C20,Гуров!C20) -> 6 | D20: =AVERAGE(Болгов!D20,Спицин!D20,Гуров!D20) -> 7 | E20: =AVERAGE(Болгов!E20,Спицин!E20,Гуров!E20) -> 8.3333333
A21: Менеджер паролей | B21: Простота реализации | C21: =AVERAGE(Болгов!C21,Спицин!C21,Гуров!C21) -> 2.6666667 | D21: =AVERAGE(Болгов!D21,Спицин!D21,Гуров!D21) -> 3.6666667 | E21: =AVERAGE(Болгов!E21,Спицин!E21,Гуров!E21) -> 5.3333333
A22: Менеджер паролей | B22: Интерес команды | C22: =AVERAGE(Болгов!C22,Спицин!C22,Гуров!C22) -> 4 | D22: =AVERAGE(Болгов!D22,Спицин!D22,Гуров!D22) -> 5 | E22: =AVERAGE(Болгов!E22,Спицин!E22,Гуров!E22) -> 6
A23: Менеджер паролей | B23: Масштабируемость | C23: =AVERAGE(Болгов!C23,Спицин!C23,Гуров!C23) -> 3 | D23: =AVERAGE(Болгов!D23,Спицин!D23,Гуров!D23) -> 4 | E23: =AVERAGE(Болгов!E23,Спицин!E23,Гуров!E23) -> 5
... A27: Markdown-редактор | B27: Масштабируемость | C27: =AVERAGE(Болгов!C27,Спицин!C27,Гуров!C27) -> 4.6666667 | D27: =AVERAGE(Болгов!D27,Спицин!D27,Гуров!D27) -> 6 | E27: =AVERAGE(Болгов!E27,Спицин!E27,Гуров!E27) -> 7

Sheet TOPSIS
A1: Нечёткий коллективный TOPSIS
A3: Максимум шкалы оценок | B3: 9
A5: Таблица 1. Агрегированные веса критериев
A6: Критерий | B6: a (мин.) | C6: b (среднее) | D6: c (макс.) | E6: Норм. вес a | F6: Норм. вес b | G6: Норм. вес c
A7: Востребованность | B7: =MIN(Болгов!B5,Спицин!B5,Гуров!B5) -> 5 | C7: =AVERAGE(Болгов!C5,Спицин!C5,Гуров!C5) -> 6.6666667 | D7: =MAX(Болгов!D5,Спицин!D5,Гуров!D5) -> 8 | E7: =B7/$B$3 -> 0.55555556 | F7: =C7/$B$3 -> 0.74074074 | G7: =D7/$B$3 -> 0.88888889
A8: Простота реализации | B8: =MIN(Болгов!B6,Спицин!B6,Гуров!B6) -> 6 | C8: =AVERAGE(Болгов!C6,Спицин!C6,Гуров!C6) -> 7.6666667 | D8: =MAX(Болгов!D6,Спицин!D6,Гуров!D6) -> 9 | E8: =B8/$B$3 -> 0.66666667 | F8: =C8/$B$3 -> 0.85185185 | G8: =D8/$B$3 -> 1
A9: Интерес команды | B9: =MIN(Болгов!B7,Спицин!B7,Гуров!B7) -> 4 | C9: =AVERAGE(Болгов!C7,Спицин!C7,Гуров!C7) -> 6 | D9: =MAX(Болгов!D7,Спицин!D7,Гуров!D7) -> 8 | E9: =B9/$B$3 -> 0.44444444 | F9: =C9/$B$3 -> 0.66666667 | G9: =D9/$B$3 -> 0.88888889
A10: Масштабируемость | B10: =MIN(Болгов!B8,Спицин!B8,Гуров!B8) -> 2 | C10: =AVERAGE(Болгов!C8,Спицин!C8,Гуров!C8) -> 4 | D10: =MAX(Болгов!D8,Спицин!D8,Гуров!D8) -> 6 | E10: =B10/$B$3 -> 0.22222222 | F10: =C10/$B$3 -> 0.44444444 | G10: =D10/$B$3 -> 0.66666667
A12: Таблица 2. Агрегированная матрица решений (мин. / среднее / макс. по экспертам)
A13: Концепция | B13: Востребованность | E13: Простота реализации | H13: Интерес команды | K13: Масштабируемость
B14: a | C14: b | D14: c | E14: a | F14: b | G14: c | H14: a | I14: b | J14: c | K14: a | L14: b | M14: c
A15: Таск-менеджер | B15: =MIN(Болгов!C12,Спицин!C12,Гуров!C12) -> 7 | C15: =AVERAGE(Болгов!D12,Спицин!D12,Гуров!D12) -> 8 | D15: =MAX(Болгов!E12,Спицин!E12,Гуров!E12) -> 9 | E15: =MIN(Болгов!C13,Спицин!C13,Гуров!C13) -> 4 | F15: =AVERAGE(Болгов!D13,Спицин!D13,Гуров!D13) -> 5.3333333 | G15: =MAX(Болгов!E13,Спицин!E13,Гуров!E13) -> 7 | H15: =MIN(Болгов!C14,Спицин!C14,Гуров!C14) -> 3 | I15: =AVERAGE(Болгов!D14,Спицин!D14,Гуров!D14) -> 4.6666667 | J15: =MAX(Болгов!E14,Спицин!E14,Гуров!E14) -> 6 | K15: =MIN(Болгов!C15,Спицин!C15,Гуров!C15) -> 6 | L15: =AVERAGE(Болгов!D15,Спицин!D15,Гуров!D15) -> 8 | M15: =MAX(Болгов!E15,Спицин!E15,Гуров!E15) -> 9
A16: Органайзер изображений | B16: =MIN(Болгов!C16,Спицин!C16,Гуров!C16) -> 3 | C16: =AVERAGE(Болгов!D16,Спицин!D16,Гуров!D16) -> 5 | D16: =MAX(Болгов!E16,Спицин!E16,Гуров!E16) -> 6 | E16: =MIN(Болгов!C17,Спицин!C17,Гуров!C17) -> 3 | F16: =AVERAGE(Болгов!D17,Спицин!D17,Гуров!D17) -> 4 | G16: =MAX(Болгов!E17,Спицин!E17,Гуров!E17) -> 5 | H16: =MIN(Болгов!C18,Спицин!C18,Гуров!C18) -> 5 | I16: =AVERAGE(Болгов!D18,Спицин!D18,Гуров!D18) -> 6 | J16: =MAX(Болгов!E18,Спицин!E18,Гуров!E18) -> 8 | K16: =MIN(Болгов!C19,Спицин!C19,Гуров!C19) -> 4 | L16: =AVERAGE(Болгов!D19,Спицин!D19,Гуров!D19) -> 5 | M16: =MAX(Болгов!E19,Спицин!E19,Гуров!E19) -> 6
A17: Менеджер паролей | B17: =MIN(Болгов!C20,Спицин!C20,Гуров!C20) -> 6 | C17: =AVERAGE(Болгов!D20,Спицин!D20,Гуров!D20) -> 7 | D17: =MAX(Болгов!E20,Спицин!E20,Гуров!E20) -> 9 | E17: =MIN(Болгов!C21,Спицин!C21,Гуров!C21) -> 2 | F17: =AVERAGE(Болгов!D21,Спицин!D21,Гуров!D21) -> 3.6666667 | G17: =MAX(Болгов!E21,Спицин!E21,Гуров!E21) -> 6 | H17: =MIN(Болгов!C22,Спицин!C22,Гуров!C22) -> 4 | I17: =AVERAGE(Болгов!D22,Спицин!D22,Гуров!D22) -> 5 | J17: =MAX(Болгов!E22,Спицин!E22,Гуров!E22) -> 6 | K17: =MIN(Болгов!C23,Спицин!C23,Гуров!C23) -> 3 | L17: =AVERAGE(Болгов!D23,Спицин!D23,Гуров!D23) -> 4 | M17: =MAX(Болгов!E23,Спицин!E23,Гуров!E23) -> 5
A18: Markdown-редактор | B18: =MIN(Болгов!C24,Спицин!C24,Гуров!C24) -> 4 | C18: =AVERAGE(Болгов!D24,Спицин!D24,Гуров!D24) -> 6 | D18: =MAX(Болгов!E24,Спицин!E24,Гуров!E24) -> 8 | E18: =MIN(Болгов!C25,Спицин!C25,Гуров!C25) -> 7 | F18: =AVERAGE(Болгов!D25,Спицин!D25,Гуров!D25) -> 8 | G18: =MAX(Болгов!E25,Спицин!E25,Гуров!E25) -> 9 | H18: =MIN(Болгов!C26,Спицин!C26,Гуров!C26) -> 6 | I18: =AVERAGE(Болгов!D26,Спицин!D26,Гуров!D26) -> 7.6666667 | J18: =MAX(Болгов!E26,Спицин!E26,Гуров!E26) -> 9 | K18: =MIN(Болгов!C27,Спицин!C27,Гуров!C27) -> 4 | L18: =AVERAGE(Болгов!D27,Спицин!D27,Гуров!D27) -> 6 | M18: =MAX(Болгов!E27,Спицин!E27,Гуров!E27) -> 7
A19: c* (макс. верхних границ) | B19: =MAX($D$15:$D$18) -> 9 | C19: =MAX($D$15:$D$18) -> 9 | D19: =MAX($D$15:$D$18) -> 9 | E19: =MAX($G$15:$G$18) -> 9 | F19: =MAX($G$15:$G$18) -> 9 | G19: =MAX($G$15:$G$18) -> 9 | H19: =MAX($J$15:$J$18) -> 9 | I19: =MAX($J$15:$J$18) -> 9 | J19: =MAX($J$15:$J$18) -> 9 | K19: =MAX($M$15:$M$18) -> 9 | L19: =MAX($M$15:$M$18) -> 9 | M19: =MAX($M$15:$M$18) -> 9
A21: Таблица 3. Нормированная матрица решений (деление на c*)
A22: Концепция | B22: Востребованность | E22: Простота реализации | H22: Интерес команды | K22: Масштабируемость
B23: a | C23: b | D23: c | E23: a | F23: b | G23: c | H23: a | I23: b | J23: c | K23: a | L23: b | M23: c
A24: Таск-менеджер | B24: =B15/B$19 -> 0.77777778 | C24: =C15/C$19 -> 0.88888889 | D24: =D15/D$19 -> 1 | E24: =E15/E$19 -> 0.44444444 | F24: =F15/F$19 -> 0.59259259 | G24: =G15/G$19 -> 0.77777778 | H24: =H15/H$19 -> 0.33333333 | I24: =I15/I$19 -> 0.51851852 | ... M24: =M15/M$19 -> 1
A25: Органайзер изображений | B25: =B16/B$19 -> 0.33333333 | C25: =C16/C$19 -> 0.55555556 | D25: =D16/D$19 -> 0.66666667 | E25: =E16/E$19 -> 0.33333333 | F25: =F16/F$19 -> 0.44444444 | G25: =G16/G$19 -> 0.55555556 | H25: =H16/H$19 -> 0.55555556 | I25: =I16/I$19 -> 0.66666667 | ... M25: =M16/M$19 -> 0.66666667
A26: Менеджер паролей | B26: =B17/B$19 -> 0.66666667 | C26: =C17/C$19 -> 0.77777778 | D26: =D17/D$19 -> 1 | E26: =E17/E$19 -> 0.22222222 | F26: =F17/F$19 -> 0.40740741 | G26: =G17/G$19 -> 0.66666667 | H26: =H17/H$19 -> 0.44444444 | I26: =I17/I$19 -> 0.55555556 | ... M26: =M17/M$19 -> 0.55555556
A27: Markdown-редактор | B27: =B18/B$19 -> 0.44444444 | C27: =C18/C$19 -> 0.66666667 | D27: =D18/D$19 -> 0.88888889 | E27: =E18/E$19 -> 0.77777778 | F27: =F18/F$19 -> 0.88888889 | G27: =G18/G$19 -> 1 | H27: =H18/H$19 -> 0.66666667 | I27: =I18/I$19 -> 0.85185185 | ... M27: =M18/M$19 -> 0.77777778
A29: Таблица 4. Взвешенная нормированная матрица решений
A30: Концепция | B30: Востребованность | E30: Простота реализации | H30: Интерес команды | K30: Масштабируемость
B31: a | C31: b | D31: c | E31: a | F31: b | G31: c | H31: a | I31: b | J31: c | K31: a | L31: b | M31: c
A32: Таск-менеджер | B32: =B24*$E$7 -> 0.43209877 | C32: =C24*$F$7 -> 0.65843621 | D32: =D24*$G$7 -> 0.88888889 | E32: =E24*$E$8 -> 0.2962963 | F32: =F24*$F$8 -> 0.5048011 | G32: =G24*$G$8 -> 0.77777778 | H32: =H24*$E$9 -> 0.14814815 | I32: =I24*$F$9 -> 0.34567901 | J32: =J24*$G$9 -> 0.59259259 | K32: =K24*$E$10 -> 0.14814815 | L32: =L24*$F$10 -> 0.39506173 | M32: =M24*$G$10 -> 0.66666667
A33: Органайзер изображений | B33: =B25*$E$7 -> 0.18518519 | C33: =C25*$F$7 -> 0.41152263 | D33: =D25*$G$7 -> 0.59259259 | E33: =E25*$E$8 -> 0.22222222 | F33: =F25*$F$8 -> 0.37860082 | G33: =G25*$G$8 -> 0.55555556 | H33: =H25*$E$9 -> 0.24691358 | I33: =I25*$F$9 -> 0.44444444 | J33: =J25*$G$9 -> 0.79012346 | K33: =K25*$E$10 -> 0.098765432 | L33: =L25*$F$10 -> 0.24691358 | M33: =M25*$G$10 -> 0.44444444
A34: Менеджер паролей | B34: =B26*$E$7 -> 0.37037037 | C34: =C26*$F$7 -> 0.57613169 | D34: =D26*$G$7 -> 0.88888889 | E34: =E26*$E$8 -> 0.14814815 | F34: =F26*$F$8 -> 0.34705075 | G34: =G26*$G$8 -> 0.66666667 | H34: =H26*$E$9 -> 0.19753086 | I34: =I26*$F$9 -> 0.37037037 | J34: =J26*$G$9 -> 0.59259259 | K34: =K26*$E$10 -> 0.074074074 | L34: =L26*$F$10 -> 0.19753086 | M34: =M26*$G$10 -> 0.37037037
A35: Markdown-редактор | B35: =B27*$E$7 -> 0.24691358 | C35: =C27*$F$7 -> 0.49382716 | D35: =D27*$G$7 -> 0.79012346 | E35: =E27*$E$8 -> 0.51851852 | F35: =F27*$F$8 -> 0.75720165 | G35: =G27*$G$8 -> 1 | H35: =H27*$E$9 -> 0.2962963 | I35: =I27*$F$9 -> 0.56790123 | J35: =J27*$G$9 -> 0.88888889 | K35: =K27*$E$10 -> 0.098765432 | L35: =L27*$F$10 -> 0.2962963 | M35: =M27*$G$10 -> 0.51851852
A37: Таблица 5. Расстояния до идеала и антиидеала, коэффициент близости
B38: Расстояние до идеала (1; 1; 1) | G38: Расстояние до антиидеала (0; 0; 0)
A39: Концепция | B39: Востребованность | C39: Простота реализации | D39: Интерес команды | E39: Масштабируемость | F39: Σ d⁺ | G39: Востребованность | H39: Простота реализации | I39: Интерес команды | J39: Масштабируемость | K39: Σ d⁻ | L39: CC | M39: Место
A40: Таск-менеджер | B40: =SQRT(((B32-1)^2+(C32-1)^2+(D32-1)^2)/3) -> 0.38795331 | C40: =SQRT(((E32-1)^2+(F32-1)^2+(G32-1)^2)/3) -> 0.51309634 | D40: =SQRT(((H32-1)^2+(I32-1)^2+(J32-1)^2)/3) -> 0.66326675 | E40: =SQRT(((K32-1)^2+(L32-1)^2+(M32-1)^2)/3) -> 0.63317007 | F40: =SUM(B40:E40) -> 2.1974865 | G40: =SQRT((B32^2+C32^2+D32^2)/3) -> 0.68565566 | H40: =SQRT((E32^2+F32^2+G32^2)/3) -> 0.5620065 | I40: =SQRT((H32^2+I32^2+J32^2)/3) -> 0.40521921 | J40: =SQRT((K32^2+L32^2+M32^2)/3) -> 0.45550927 | K40: =SUM(G40:J40) -> 2.1083906 | L40: =K40/(F40+K40) -> 0.48965416 | M40: =RANK(L40,$L$40:$L$43) -> 2
A41: Органайзер изображений | B41: =SQRT(((B33-1)^2+(C33-1)^2+(D33-1)^2)/3) -> 0.62615482 | C41: =SQRT(((E33-1)^2+(F33-1)^2+(G33-1)^2)/3) -> 0.62944581 | D41: =SQRT(((H33-1)^2+(I33-1)^2+(J33-1)^2)/3) -> 0.55372355 | E41: =SQRT(((K33-1)^2+(L33-1)^2+(M33-1)^2)/3) -> 0.75011219 | F41: =SUM(B41:E41) -> 2.5594364 | G41: =SQRT((B33^2+C33^2+D33^2)/3) -> 0.43004279 | H41: =SQRT((E33^2+F33^2+G33^2)/3) -> 0.40880447 | I41: =SQRT((H33^2+I33^2+J33^2)/3) -> 0.54246114 | J41: =SQRT((K33^2+L33^2+M33^2)/3) -> 0.2990272 | K41: =SUM(G41:J41) -> 1.6803356 | L41: =K41/(F41+K41) -> 0.39632688 | M41: =RANK(L41,$L$40:$L$43) -> 4
A42: Менеджер паролей | B42: =SQRT(((B34-1)^2+(C34-1)^2+(D34-1)^2)/3) -> 0.4428858 | C42: =SQRT(((E34-1)^2+(F34-1)^2+(G34-1)^2)/3) -> 0.6488722 | D42: =SQRT(((H34-1)^2+(I34-1)^2+(J34-1)^2)/3) -> 0.63413221 | E42: =SQRT(((K34-1)^2+(L34-1)^2+(M34-1)^2)/3) -> 0.79534668 | F42: =SUM(B42:E42) -> 2.5212369 | G42: =SQRT((B34^2+C34^2+D34^2)/3) -> 0.64787483 | H42: =SQRT((E34^2+F34^2+G34^2)/3) -> 0.44228066 | I42: =SQRT((H34^2+I34^2+J34^2)/3) -> 0.41926866 | J42: =SQRT((K34^2+L34^2+M34^2)/3) -> 0.24608916 | K42: =SUM(G42:J42) -> 1.7555133 | L42: =K42/(F42+K42) -> 0.41047834 | M42: =RANK(L42,$L$40:$L$43) -> 3
A43: Markdown-редактор | B43: =SQRT(((B35-1)^2+(C35-1)^2+(D35-1)^2)/3) -> 0.53771066 | C43: =SQRT(((E35-1)^2+(F35-1)^2+(G35-1)^2)/3) -> 0.31132805 | D43: =SQRT(((H35-1)^2+(I35-1)^2+(J35-1)^2)/3) -> 0.48105922 | E43: =SQRT(((K35-1)^2+(L35-1)^2+(M35-1)^2)/3) -> 0.71629767 | F43: =SUM(B43:E43) -> 2.0463956 | G43: =SQRT((B35^2+C35^2+D35^2)/3) -> 0.55651495 | H43: =SQRT((E35^2+F35^2+G35^2)/3) -> 0.78362742 | I43: =SQRT((H35^2+I35^2+J35^2)/3) -> 0.63256798 | J43: =SQRT((K35^2+L35^2+M35^2)/3) -> 0.3494794 | K43: =SUM(G43:J43) -> 2.3221898 | L43: =K43/(F43+K43) -> 0.53156561 | M43: =RANK(L43,$L$40:$L$43) -> 1
A45: Лучшая концепция | B45: =INDEX($A$40:$A$43,MATCH(1,$M$40:$M$43,0)) -> Markdown-редактор
A47: Примечания
A48: 1. Оценки экспертов агрегированы по Чену: a – минимум нижних границ, b – среднее ожидаемых оценок, c – максимум верхних границ.
...

Sheet МАИ
A1: Коллективный МАИ
A3: Индекс случайной согласованности RI (n = 4) | B3: 0.9
A5: Таблица 1. Парные сравнения критериев (агрегированная матрица)
A6: Критерий | B6: Востребованность | C6: Простота реализации | D6: Интерес команды | E6: Масштабируемость | F6: Геом. среднее строки | G6: Вес
A7: Востребованность | B7: 1 | C7: =GEOMEAN(IF(Болгов!C5>=Болгов!C6,1+Болгов!C5-Болгов!C6,1/(1+Болгов!C6-Болгов!C5)),IF(Спицин!C5>=Спицин!C6,1+Спицин!C5-Спицин!C6,1/(1+Спицин!C6-Спицин!C5)),IF(Гуров!C5>=Гуров!C6,1+Гуров!C5-Гуров!C6,1/(1+Гуров!C6-Гуров!C5))) -> 0.5 | D7: =GEOMEAN(IF(Болгов!C5>=Болгов!C7,1+Болгов!C5-Болгов!C7,1/(1+Болгов!C7-Болгов!C5)),IF(Спицин!C5>=Спицин!C7,1+Спицин!C5-Спицин!C7,1/(1+Спицин!C7-Спицин!C5)),IF(Гуров!C5>=Гуров!C7,1+Гуров!C5-Гуров!C7,1/(1+Гуров!C7-Гуров!C5))) -> 1.4422496 | E7: =GEOMEAN(IF(Болгов!C5>=Болгов!C8,1+Болгов!C5-Болгов!C8,1/(1+Болгов!C8-Болгов!C5)),IF(Спицин!C5>=Спицин!C8,1+Спицин!C5-Спицин!C8,1/(1+Спицин!C8-Спицин!C5)),IF(Гуров!C5>=Гуров!C8,1+Гуров!C5-Гуров!C8,1/(1+Гуров!C8-Гуров!C5))) -> 3.6342412 | F7: =GEOMEAN(B7:E7) -> 1.2723484 | G7: =F7/SUM(F$7:F$10) -> 0.26702689
A8: Простота реализации | B8: =1/C7 -> 2 | C8: 1 | D8: =GEOMEAN(IF(Болгов!C6>=Болгов!C7,1+Болгов!C6-Болгов!C7,1/(1+Болгов!C7-Болгов!C6)),IF(Спицин!C6>=Спицин!C7,1+Спицин!C6-Спицин!C7,1/(1+Спицин!C7-Спицин!C6)),IF(Гуров!C6>=Гуров!C7,1+Гуров!C6-Гуров!C7,1/(1+Гуров!C7-Гуров!C6))) -> 2.2894285 | E8: =GEOMEAN(IF(Болгов!C6>=Болгов!C8,1+Болгов!C6-Болгов!C8,1/(1+Болгов!C8-Болгов!C6)),IF(Спицин!C6>=Спицин!C8,1+Спицин!C6-Спицин!C8,1/(1+Спицин!C8-Спицин!C6)),IF(Гуров!C6>=Гуров!C8,1+Гуров!C6-Гуров!C8,1/(1+Гуров!C8-Гуров!C6))) -> 4.6415888 | F8: =GEOMEAN(B8:E8) -> 2.1471181 | G8: =F8/SUM(F$7:F$10) -> 0.45061422
A9: Интерес команды | B9: =1/D7 -> 0.69336127 | C9: =1/D8 -> 0.43679023 | D9: 1 | E9: =GEOMEAN(IF(Болгов!C7>=Болгов!C8,1+Болгов!C7-Болгов!C8,1/(1+Болгов!C8-Болгов!C7)),IF(Спицин!C7>=Спицин!C8,1+Спицин!C7-Спицин!C8,1/(1+Спицин!C8-Спицин!C7)),IF(Гуров!C7>=Гуров!C8,1+Гуров!C7-Гуров!C8,1/(1+Гуров!C8-Гуров!C7))) -> 2.8844991 | F9: =GEOMEAN(B9:E9) -> 0.96677571 | G9: =F9/SUM(F$7:F$10) -> 0.20289656
A10: Масштабируемость | B10: =1/E7 -> 0.2751606 | C10: =1/E8 -> 0.21544347 | D10: =1/E9 -> 0.34668064 | E10: 1 | F10: =GEOMEAN(B10:E10) -> 0.37862762 | G10: =F10/SUM(F$7:F$10) -> 0.079462322
A11: Сумма столбца | B11: =SUM(B7:B10) -> 3.9685219 | C11: =SUM(C7:C10) -> 2.1522337 | D11: =SUM(D7:D10) -> 5.0783587 | E11: =SUM(E7:E10) -> 12.160329
A12: λmax | B12: =B11*G7+C11*G8+D11*G9+E11*G10 -> 4.0261987
A13: ИС (индекс согласованности) | B13: =(B12-4)/(4-1) -> 0.0087328988
A14: ОС (отношение согласованности) | B14: =B13/$B$3 -> 0.0097032209 | C14: =IF(B14<=0.1,"приемлемо","пересмотреть оценки") -> приемлемо
A17: Таблица 2. Парные сравнения концепций по критерию «Востребованность»
A18: Концепция | B18: Таск-менеджер | C18: Органайзер изображений | D18: Менеджер паролей | E18: Markdown-редактор | F18: Геом. среднее строки | G18: Вес
A19: Таск-менеджер | B19: 1 | C19: =GEOMEAN(IF(Болгов!D12>=Болгов!D16,1+Болгов!D12-Болгов!D16,1/(1+Болгов!D16-Болгов!D12)),IF(Спицин!D12>=Спицин!D16,1+Спицин!D12-Спицин!D16,1/(1+Спицин!D16-Спицин!D12)),IF(Гуров!D12>=Гуров!D16,1+Гуров!D12-Гуров!D16,1/(1+Гуров!D16-Гуров!D12))) -> 4 | D19: =GEOMEAN(IF(Болгов!D12>=Болгов!D20,1+Болгов!D12-Болгов!D20,1/(1+Болгов!D20-Болгов!D12)),IF(Спицин!D12>=Спицин!D20,1+Спицин!D12-Спицин!D20,1/(1+Спицин!D20-Спицин!D12)),IF(Гуров!D12>=Гуров!D20,1+Гуров!D12-Гуров!D20,1/(1+Гуров!D20-Гуров!D12))) -> 2 | E19: =GEOMEAN(IF(Болгов!D12>=Болгов!D24,1+Болгов!D12-Болгов!D24,1/(1+Болгов!D24-Болгов!D12)),IF(Спицин!D12>=Спицин!D24,1+Спицин!D12-Спицин!D24,1/(1+Спицин!D24-Спицин!D12)),IF(Гуров!D12>=Гуров!D24,1+Гуров!D12-Гуров!D24,1/(1+Гуров!D24-Гуров!D12))) -> 3 | F19: =GEOMEAN(B19:E19) -> 2.2133638 | G19: =F19/SUM(F$19:F$22) -> 0.46684856
A20: Органайзер изображений | B20: =1/C19 -> 0.25 | C20: 1 | D20: =GEOMEAN(IF(Болгов!D16>=Болгов!D20,1+Болгов!D16-Болгов!D20,1/(1+Болгов!D20-Болгов!D16)),IF(Спицин!D16>=Спицин!D20,1+Спицин!D16-Спицин!D20,1/(1+Спицин!D20-Спицин!D16)),IF(Гуров!D16>=Гуров!D20,1+Гуров!D16-Гуров!D20,1/(1+Гуров!D20-Гуров!D16))) -> 0.33333333 | E20: =GEOMEAN(IF(Болгов!D16>=Болгов!D24,1+Болгов!D16-Болгов!D24,1/(1+Болгов!D24-Болгов!D16)),IF(Спицин!D16>=Спицин!D24,1+Спицин!D16-Спицин!D24,1/(1+Спицин!D24-Спицин!D16)),IF(Гуров!D16>=Гуров!D24,1+Гуров!D16-Гуров!D24,1/(1+Гуров!D24-Гуров!D16))) -> 0.5 | F20: =GEOMEAN(B20:E20) -> 0.451801 | G20: =F20/SUM(F$19:F$22) -> 0.095295064
A21: Менеджер паролей | B21: =1/D19 -> 0.5 | C21: =1/D20 -> 3 | D21: 1 | E21: =GEOMEAN(IF(Болгов!D20>=Болгов!D24,1+Болгов!D20-Болгов!D24,1/(1+Болгов!D24-Болгов!D20)),IF(Спицин!D20>=Спицин!D24,1+Спицин!D20-Спицин!D24,1/(1+Спицин!D24-Спицин!D20)),IF(Гуров!D20>=Гуров!D24,1+Гуров!D20-Гуров!D24,1/(1+Гуров!D24-Гуров!D20))) -> 2 | F21: =GEOMEAN(B21:E21) -> 1.316074 | G21: =F21/SUM(F$19:F$22) -> 0.27758982
A22: Markdown-редактор | B22: =1/E19 -> 0.33333333 | C22: =1/E20 -> 2 | D22: =1/E21 -> 0.5 | E22: 1 | F22: =GEOMEAN(B22:E22) -> 0.75983569 | G22: =F22/SUM(F$19:F$22) -> 0.16026656
A23: Сумма столбца | B23: =SUM(B19:B22) -> 2.0833333 | C23: =SUM(C19:C22) -> 10 | D23: =SUM(D19:D22) -> 3.8333333 | E23: =SUM(E19:E22) -> 6.5
A24: λmax | B24: =B23*G19+C23*G20+D23*G21+E23*G22 -> 4.0313787
A25: ИС (индекс согласованности) | B25: =(B24-4)/(4-1) -> 0.010459574
A26: ОС (отношение согласованности) | B26: =B25/$B$3 -> 0.011621749 | C26: =IF(B26<=0.1,"приемлемо","пересмотреть оценки") -> приемлемо
A29: Таблица 3. Парные сравнения концепций по критерию «Простота реализации»
A30: Концепция | B30: Таск-менеджер | C30: Органайзер изображений | D30: Менеджер паролей | E30: Markdown-редактор | F30: Геом. среднее строки | G30: Вес
A31: Таск-менеджер | B31: 1 | C31: =GEOMEAN(IF(Болгов!D13>=Болгов!D17,1+Болгов!D13-Болгов!D17,1/(1+Болгов!D17-Болгов!D13)),IF(Спицин!D13>=Спицин!D17,1+Спицин!D13-Спицин!D17,1/(1+Спицин!D17-Спицин!D13)),IF(Гуров!D13>=Гуров!D17,1+Гуров!D13-Гуров!D17,1/(1+Гуров!D17-Гуров!D13))) -> 2.2894285 | D31: =GEOMEAN(IF(Болгов!D13>=Болгов!D21,1+Болгов!D13-Болгов!D21,1/(1+Болгов!D21-Болгов!D13)),IF(Спицин!D13>=Спицин!D21,1+Спицин!D13-Спицин!D21,1/(1+Спицин!D21-Спицин!D13)),IF(Гуров!D13>=Гуров!D21,1+Гуров!D13-Гуров!D21,1/(1+Гуров!D21-Гуров!D13))) -> 2.5198421 | E31: =GEOMEAN(IF(Болгов!D13>=Болгов!D25,1+Болгов!D13-Болгов!D25,1/(1+Болгов!D25-Болгов!D13)),IF(Спицин!D13>=Спицин!D25,1+Спицин!D13-Спицин!D25,1/(1+Спицин!D25-Спицин!D13)),IF(Гуров!D13>=Гуров!D25,1+Гуров!D13-Гуров!D25,1/(1+Гуров!D25-Гуров!D13))) -> 0.2751606 | F31: =GEOMEAN(B31:E31) -> 1.122462 | G31: =F31/SUM(F$31:F$34) -> 0.21073097
A32: Органайзер изображений | B32: =1/C31 -> 0.43679023 | C32: 1 | D32: =GEOMEAN(IF(Болгов!D17>=Болгов!D21,1+Болгов!D17-Болгов!D21,1/(1+Болгов!D21-Болгов!D17)),IF(Спицин!D17>=Спицин!D21,1+Спицин!D17-Спицин!D21,1/(1+Спицин!D21-Спицин!D17)),IF(Гуров!D17>=Гуров!D21,1+Гуров!D17-Гуров!D21,1/(1+Гуров!D21-Гуров!D17))) -> 1.259921 | E32: =GEOMEAN(IF(Болгов!D17>=Болгов!D25,1+Болгов!D17-Болгов!D25,1/(1+Болгов!D25-Болгов!D17)),IF(Спицин!D17>=Спицин!D25,1+Спицин!D17-Спицин!D25,1/(1+Спицин!D25-Спицин!D17)),IF(Гуров!D17>=Гуров!D25,1+Гуров!D17-Гуров!D25,1/(1+Гуров!D25-Гуров!D17))) -> 0.2 | F32: =GEOMEAN(B32:E32) -> 0.57598551 | G32: =F32/SUM(F$31:F$34) -> 0.10813549
A33: Менеджер паролей | B33: =1/D31 -> 0.39685026 | C33: =1/D32 -> 0.79370053 | D33: 1 | E33: =GEOMEAN(IF(Болгов!D21>=Болгов!D25,1+Болгов!D21-Болгов!D25,1/(1+Болгов!D25-Болгов!D21)),IF(Спицин!D21>=Спицин!D25,1+Спицин!D21-Спицин!D25,1/(1+Спицин!D25-Спицин!D21)),IF(Гуров!D21>=Гуров!D25,1+Гуров!D21-Гуров!D25,1/(1+Гуров!D25-Гуров!D21))) -> 0.18820721 | F33: =GEOMEAN(B33:E33) -> 0.49343494 | G33: =F33/SUM(F$31:F$34) -> 0.092637452
A34: Markdown-редактор | B34: =1/E31 -> 3.6342412 | C34: =1/E32 -> 5 | D34: =1/E33 -> 5.3132928 | E34: 1 | F34: =GEOMEAN(B34:E34) -> 3.1346343 | G34: =F34/SUM(F$31:F$34) -> 0.58849608
A35: Сумма столбца | B35: =SUM(B31:B34) -> 5.4678817 | C35: =SUM(C31:C34) -> 9.083129 | D35: =SUM(D31:D34) -> 10.093056 | E35: =SUM(E31:E34) -> 1.6633678
A36: λmax | B36: =B35*G31+C35*G32+D35*G33+E35*G34 -> 4.0483411
A37: ИС (индекс согласованности) | B37: =(B36-4)/(4-1) -> 0.016113692
A38: ОС (отношение согласованности) | B38: =B37/$B$3 -> 0.017904102 | C38: =IF(B38<=0.1,"приемлемо","пересмотреть оценки") -> приемлемо
A41: Таблица 4. Парные сравнения концепций по критерию «Интерес команды»
A42: Концепция | B42: Таск-менеджер | C42: Органайзер изображений | D42: Менеджер паролей | E42: Markdown-редактор | F42: Геом. среднее строки | G42: Вес
A43: Таск-менеджер | B43: 1 | C43: =GEOMEAN(IF(Болгов!D14>=Болгов!D18,1+Болгов!D14-Болгов!D18,1/(1+Болгов!D18-Болгов!D14)),IF(Спицин!D14>=Спицин!D18,1+Спицин!D14-Спицин!D18,1/(1+Спицин!D18-Спицин!D14)),IF(Гуров!D14>=Гуров!D18,1+Гуров!D14-Гуров!D18,1/(1+Гуров!D18-Гуров!D14))) -> 0.43679023 | D43: =GEOMEAN(IF(Болгов!D14>=Болгов!D22,1+Болгов!D14-Болгов!D22,1/(1+Болгов!D22-Болгов!D14)),IF(Спицин!D14>=Спицин!D22,1+Спицин!D14-Спицин!D22,1/(1+Спицин!D22-Спицин!D14)),IF(Гуров!D14>=Гуров!D22,1+Гуров!D14-Гуров!D22,1/(1+Гуров!D22-Гуров!D14))) -> 0.79370053 | E43: =GEOMEAN(IF(Болгов!D14>=Болгов!D26,1+Болгов!D14-Болгов!D26,1/(1+Болгов!D26-Болгов!D14)),IF(Спицин!D14>=Спицин!D26,1+Спицин!D14-Спицин!D26,1/(1+Спицин!D26-Спицин!D14)),IF(Гуров!D14>=Гуров!D26,1+Гуров!D14-Гуров!D26,1/(1+Гуров!D26-Гуров!D14))) -> 0.25543648 | F43: =GEOMEAN(B43:E43) -> 0.54551051 | G43: =F43/SUM(F$43:F$46) -> 0.11337537
A44: Органайзер изображений | B44: =1/C43 -> 2.2894285 | C44: 1 | D44: =GEOMEAN(IF(Болгов!D18>=Болгов!D22,1+Болгов!D18-Болгов!D22,1/(1+Болгов!D22-Болгов!D18)),IF(Спицин!D18>=Спицин!D22,1+Спицин!D18-Спицин!D22,1/(1+Спицин!D22-Спицин!D18)),IF(Гуров!D18>=Гуров!D22,1+Гуров!D18-Гуров!D22,1/(1+Гуров!D22-Гуров!D18))) -> 2 | E44: =GEOMEAN(IF(Болгов!D18>=Болгов!D26,1+Болгов!D18-Болгов!D26,1/(1+Болгов!D26-Болгов!D18)),IF(Спицин!D18>=Спицин!D26,1+Спицин!D18-Спицин!D26,1/(1+Спицин!D26-Спицин!D18)),IF(Гуров!D18>=Гуров!D26,1+Гуров!D18-Гуров!D26,1/(1+Гуров!D26-Гуров!D18))) -> 0.38157141 | F44: =GEOMEAN(B44:E44) -> 1.1496965 | G44: =F44/SUM(F$43:F$46) -> 0.23894548
A45: Менеджер паролей | B45: =1/D43 -> 1.259921 | C45: =1/D44 -> 0.5 | D45: 1 | E45: =GEOMEAN(IF(Болгов!D22>=Болгов!D26,1+Болгов!D22-Болгов!D26,1/(1+Болгов!D26-Болгов!D22)),IF(Спицин!D22>=Спицин!D26,1+Спицин!D22-Спицин!D26,1/(1+Спицин!D26-Спицин!D22)),IF(Гуров!D22>=Гуров!D26,1+Гуров!D22-Гуров!D26,1/(1+Гуров!D26-Гуров!D22))) -> 0.2751606 | F45: =GEOMEAN(B45:E45) -> 0.64524537 | G45: =F45/SUM(F$43:F$46) -> 0.13410361
A46: Markdown-редактор | B46: =1/E43 -> 3.9148676 | C46: =1/E44 -> 2.6207414 | D46: =1/E45 -> 3.6342412 | E46: 1 | F46: =GEOMEAN(B46:E46) -> 2.4710911 | G46: =F46/SUM(F$43:F$46) -> 0.51357554
A47: Сумма столбца | B47: =SUM(B43:B46) -> 8.4642172 | C47: =SUM(C43:C46) -> 4.5575316 | D47: =SUM(D43:D46) -> 7.4279417 | E47: =SUM(E43:E46) -> 1.9121685
A48: λmax | B48: =B47*G43+C47*G44+D47*G45+E47*G46 -> 4.0267921
...
